<?xml version="1.0"?>
<robot xmlns:xacro="http://www.ros.org/wiki/xacro">
    <xacro:include filename="$(find fishbot_description)/urdf/fishbot/common_inertia.xacro"/>
    <!-- 机器人左右轮子部件 -->
    <xacro:macro name="wheel_xacro" params="wheel_name xyz">
        <link name="${wheel_name}_link">
            <!-- 部件的外观描述 -->
            <visual>
                 <!-- 沿着几何中心的偏移和旋转量 轮子翻滚90度，弧度制 -->
                <origin xyz="0 0 0" rpy="1.57079 0 0" />
                <geometry>
                    <cylinder radius="0.032" length="0.04"/> 
                </geometry>
                <material name="yellow">
                    <color rgba="1 1 0 0.8" />
                </material>
            </visual>
            <collision>
                <!-- 沿着几何中心的偏移和旋转量 轮子翻滚90度，弧度制 -->
                <origin xyz="0 0 0" rpy="1.57079 0 0" />
                <geometry>
                    <cylinder radius="0.032" length="0.04"/> 
                </geometry>
                <material name="yellow">
                    <color rgba="1 1 0 0.8" />
                </material>
            </collision>
            <!-- 添加惯性和质量 -->
            <xacro:cylinder_inertia m="0.05" r="0.032" h="0.04"/>
        </link>
        <!-- 机器人关节 -->
        <joint name="${wheel_name}_joint" type="continuous">
            <!-- 父部件 -->
            <parent link="base_link" />
            <!-- 子部件 -->
            <child link="${wheel_name}_link" />
            <!-- 子部件相对父部件的平移和旋转 -->
            <origin xyz="${xyz}" rpy="0 0 0"/>
            <!-- 轮子绕y旋转 -->
            <axis xyz="0.0 1 0.0"/>
        </joint>
        <gazebo reference="${wheel_name}_link">
            <!--切向量的摩擦系数  -->
            <mu1 value="20.0"/>
             <!--法向的摩擦系数  -->
            <mu2 value="20.0"/>
             <!--接触的刚度系数  -->
            <kp value="1000000000.0"/>
             <!--阻尼系数  -->
            <kd value="1.0"/>
        </gazebo>
    </xacro:macro>
</robot>